Workbook

Sheet README
A1: Healthcare MIS Practice Dataset (dummy data, no real patients)
A3: Scenario: you are an MIS Executive for a medical billing (RCM) team of 10 AR agents in 3 teams. You report to the operations manager.
A4: Aging / report date: 15-Oct-2026
A6: Sheets
A7: Claims_Raw: 1,010 rows. One row per claim (some duplicates). Columns: Claim ID, Patient ID, Facility, Payer, DOS, Submission Date, Billed Amount, Paid Amount, Status, Denial Reason, Assigned Agent.
A8: Agents: 10 agents with Team Lead and daily target (accounts per day).
A9: Daily_Productivity: daily work log, 1-Sep-2026 to 15-Oct-2026 (weekdays). Columns: Work Date, Agent, Accounts Worked, Hours Logged, Quality %.
A11: Rules
A12: Status values: Paid, Denied, Pending. Only Pending claims count as outstanding AR.
A13: Paid Amount is blank for Pending claims and 0 for Denied claims.
A15: Planted data issues (Claims_Raw)
A16: 1. 10 duplicate rows (same Claim ID twice)
... A20: 5. Agent names in lowercase or with extra spaces

Sheet Claims_Clean
A1: Claim ID | B1: Patient ID | C1: Facility | D1: Payer_clean | E1: DOS | F1: Submission Date | G1: Billed Amount | H1: Paid Amount | I1: Status_clean | J1: Denial Reason_clean | K1: Agent_clean | L1: Age_Days | M1: Aging_Bucket | N1: Outstanding_Amount | O1: Team_Lead | P1: Denied_Amount
A2: C20001 | B2: P-1411 | C2: Green Valley Health | D2: UnitedHealthcare | E2: 46234 | F2: 46254 | G2: 12200 | H2: 0 | I2: Denied | J2: Duplicate Claim | K2: Amit V | L2: =MIS_Report!$B$2-F2 -> 56 | M2: {=_xlfn.IFS(L2<=30,"0-30",L2<=60,"31-60",L2<=90,"61-90",TRUE,"90+")} -> 31-60 | N2: =IF(I2="Pending",G2-H2,0) -> 0 | O2: =VLOOKUP(K2,Agents!$A$1:$C$11,2,0) -> Manish Arora | P2: =IF(I2="Denied",G2,0) -> 12200
A3: C20002 | B3: P-1324 | C3: City Care Clinic | D3: UnitedHealthcare | E3: 46054 | F3: 46071 | G3: 8050 | H3: 7652.9 | I3: Paid | K3: Vikas R | L3: =MIS_Report!$B$2-F3 -> 239 | M3: {=_xlfn.IFS(L3<=30,"0-30",L3<=60,"31-60",L3<=90,"61-90",TRUE,"90+")} -> 90+ | N3: =IF(I3="Pending",G3-H3,0) -> 0 | O3: =VLOOKUP(K3,Agents!$A$1:$C$11,2,0) -> Sunita Rao | P3: =IF(I3="Denied",G3,0) -> 0
A4: C20003 | B4: P-1032 | C4: City Care Clinic | D4: Medicare | E4: 46246 | F4: 46254 | G4: 675 | I4: Pending | K4: Neha G | L4: =MIS_Report!$B$2-F4 -> 56 | M4: {=_xlfn.IFS(L4<=30,"0-30",L4<=60,"31-60",L4<=90,"61-90",TRUE,"90+")} -> 31-60 | N4: =IF(I4="Pending",G4-H4,0) -> 675 | O4: =VLOOKUP(K4,Agents!$A$1:$C$11,2,0) -> Manish Arora | P4: =IF(I4="Denied",G4,0) -> 0
A5: C20004 | B5: P-1327 | C5: Apex Ortho Center | D5: UnitedHealthcare | E5: 46021 | F5: 46038 | G5: 8650 | H5: 0 | I5: Denied | J5: Coding Error | K5: Priya K | L5: =MIS_Report!$B$2-F5 -> 272 | M5: {=_xlfn.IFS(L5<=30,"0-30",L5<=60,"31-60",L5<=90,"61-90",TRUE,"90+")} -> 90+ | N5: =IF(I5="Pending",G5-H5,0) -> 0 | O5: =VLOOKUP(K5,Agents!$A$1:$C$11,2,0) -> Manish Arora | P5: =IF(I5="Denied",G5,0) -> 8650
A6: C20005 | B6: P-1477 | C6: City Care Clinic | D6: Cigna | E6: 46246 | F6: 46257 | G6: 10700 | I6: Pending | K6: Pooja M | L6: =MIS_Report!$B$2-F6 -> 53 | M6: {=_xlfn.IFS(L6<=30,"0-30",L6<=60,"31-60",L6<=90,"61-90",TRUE,"90+")} -> 31-60 | N6: =IF(I6="Pending",G6-H6,0) -> 10700 | O6: =VLOOKUP(K6,Agents!$A$1:$C$11,2,0) -> Sunita Rao | P6: =IF(I6="Denied",G6,0) -> 0
A7: C20006 | B7: P-1055 | C7: Apex Ortho Center | D7: Aetna | E7: 46121 | F7: 46140 | G7: 7675 | H7: 4594 | I7: Paid | K7: Rahul S | L7: =MIS_Report!$B$2-F7 -> 170 | M7: {=_xlfn.IFS(L7<=30,"0-30",L7<=60,"31-60",L7<=90,"61-90",TRUE,"90+")} -> 90+ | N7: =IF(I7="Pending",G7-H7,0) -> 0 | O7: =VLOOKUP(K7,Agents!$A$1:$C$11,2,0) -> Manish Arora | P7: =IF(I7="Denied",G7,0) -> 0
A8: C20007 | B8: P-1026 | C8: Green Valley Health | D8: Aetna | E8: 46014 | F8: 46023 | G8: 5650 | I8: Pending | K8: Vikas R | L8: =MIS_Report!$B$2-F8 -> 287 | M8: {=_xlfn.IFS(L8<=30,"0-30",L8<=60,"31-60",L8<=90,"61-90",TRUE,"90+")} -> 90+ | N8: =IF(I8="Pending",G8-H8,0) -> 5650 | O8: =VLOOKUP(K8,Agents!$A$1:$C$11,2,0) -> Sunita Rao | P8: =IF(I8="Denied",G8,0) -> 0
A9: C20008 | B9: P-1398 | C9: Apex Ortho Center | D9: Medicaid | E9: 46232 | F9: 46237 | G9: 14775 | I9: Pending | K9: Sandeep Y | L9: =MIS_Report!$B$2-F9 -> 73 | M9: {=_xlfn.IFS(L9<=30,"0-30",L9<=60,"31-60",L9<=90,"61-90",TRUE,"90+")} -> 61-90 | N9: =IF(I9="Pending",G9-H9,0) -> 14775 | O9: =VLOOKUP(K9,Agents!$A$1:$C$11,2,0) -> Sunita Rao | P9: =IF(I9="Denied",G9,0) -> 0
A10: C20009 | B10: P-1051 | C10: City Care Clinic | D10: Medicare | E10: 46190 | F10: 46193 | G10: 10775 | H10: 7120.92 | I10: Paid | K10: Anjali T | L10: =MIS_Report!$B$2-F10 -> 117 | M10: {=_xlfn.IFS(L10<=30,"0-30",L10<=60,"31-60",L10<=90,"61-90",TRUE,"90+")} -> 90+ | N10: =IF(I10="Pending",G10-H10,0) -> 0 | O10: =VLOOKUP(K10,Agents!$A$1:$C$11,2,0) -> Deepak Nair | P10: =IF(I10="Denied",G10,0) -> 0
A11: C20010 | B11: P-1067 | C11: Green Valley Health | D11: Cigna | E11: 46093 | F11: 46113 | G11: 5100 | H11: 4484.7 | I11: Paid | K11: Priya K | L11: =MIS_Report!$B$2-F11 -> 197 | M11: {=_xlfn.IFS(L11<=30,"0-30",L11<=60,"31-60",L11<=90,"61-90",TRUE,"90+")} -> 90+ | N11: =IF(I11="Pending",G11-H11,0) -> 0 | O11: =VLOOKUP(K11,Agents!$A$1:$C$11,2,0) -> Manish Arora | P11: =IF(I11="Denied",G11,0) -> 0
A12: C20011 | B12: P-1303 | C12: Apex Ortho Center | D12: Self Pay | E12: 46209 | F12: 46225 | G12: 5725 | H12: 0 | I12: Denied | J12: Incorrect Patient Info | K12: Rahul S | L12: =MIS_Report!$B$2-F12 -> 85 | M12: {=_xlfn.IFS(L12<=30,"0-30",L12<=60,"31-60",L12<=90,"61-90",TRUE,"90+")} -> 61-90 | N12: =IF(I12="Pending",G12-H12,0) -> 0 | O12: =VLOOKUP(K12,Agents!$A$1:$C$11,2,0) -> Manish Arora | P12: =IF(I12="Denied",G12,0) -> 5725
A13: C20012 | B13: P-1308 | C13: City Care Clinic | D13: Medicare | E13: 46122 | F13: 46130 | G13: 10375 | I13: Pending | K13: Amit V | L13: =MIS_Report!$B$2-F13 -> 180 | M13: {=_xlfn.IFS(L13<=30,"0-30",L13<=60,"31-60",L13<=90,"61-90",TRUE,"90+")} -> 90+ | N13: =IF(I13="Pending",G13-H13,0) -> 10375 | O13: =VLOOKUP(K13,Agents!$A$1:$C$11,2,0) -> Manish Arora | P13: =IF(I13="Denied",G13,0) -> 0
A14: C20013 | B14: P-1197 | C14: City Care Clinic | D14: Medicare | E14: 46115 | F14: 46132 | G14: 6900 | H14: 6373.05 | I14: Paid | K14: Neha G | L14: =MIS_Report!$B$2-F14 -> 178 | M14: {=_xlfn.IFS(L14<=30,"0-30",L14<=60,"31-60",L14<=90,"61-90",TRUE,"90+")} -> 90+ | N14: =IF(I14="Pending",G14-H14,0) -> 0 | O14: =VLOOKUP(K14,Agents!$A$1:$C$11,2,0) -> Manish Arora | P14: =IF(I14="Denied",G14,0) -> 0
A15: C20014 | B15: P-1247 | C15: Sunrise Hospital | D15: Blue Cross | E15: 46144 | F15: 46147 | G15: 9725 | H15: 9546.16 | I15: Paid | K15: Amit V | L15: =MIS_Report!$B$2-F15 -> 163 | M15: {=_xlfn.IFS(L15<=30,"0-30",L15<=60,"31-60",L15<=90,"61-90",TRUE,"90+")} -> 90+ | N15: =IF(I15="Pending",G15-H15,0) -> 0 | O15: =VLOOKUP(K15,Agents!$A$1:$C$11,2,0) -> Manish Arora | P15: =IF(I15="Denied",G15,0) -> 0
A16: C20015 | B16: P-1127 | C16: Sunrise Hospital | D16: Medicare | E16: 46089 | F16: 46101 | G16: 6125 | I16: Pending | K16: Rohit B | L16: =MIS_Report!$B$2-F16 -> 209 | M16: {=_xlfn.IFS(L16<=30,"0-30",L16<=60,"31-60",L16<=90,"61-90",TRUE,"90+")} -> 90+ | N16: =IF(I16="Pending",G16-H16,0) -> 6125 | O16: =VLOOKUP(K16,Agents!$A$1:$C$11,2,0) -> Deepak Nair | P16: =IF(I16="Denied",G16,0) -> 0
A17: C20016 | B17: P-1019 | C17: Apex Ortho Center | D17: Medicaid | E17: 46108 | F17: 46123 | G17: 12650 | H17: 7548.61 | I17: Paid | K17: Vikas R | L17: =MIS_Report!$B$2-F17 -> 187 | M17: {=_xlfn.IFS(L17<=30,"0-30",L17<=60,"31-60",L17<=90,"61-90",TRUE,"90+")} -> 90+ | N17: =IF(I17="Pending",G17-H17,0) -> 0 | O17: =VLOOKUP(K17,Agents!$A$1:$C$11,2,0) -> Sunita Rao | P17: =IF(I17="Denied",G17,0) -> 0
A18: C20017 | B18: P-1035 | C18: Sunrise Hospital | D18: Medicaid | E18: 46138 | F18: 46154 | G18: 12850 | H18: 11232.94 | I18: Paid | K18: Rohit B | L18: =MIS_Report!$B$2-F18 -> 156 | M18: {=_xlfn.IFS(L18<=30,"0-30",L18<=60,"31-60",L18<=90,"61-90",TRUE,"90+")} -> 90+ | N18: =IF(I18="Pending",G18-H18,0) -> 0 | O18: =VLOOKUP(K18,Agents!$A$1:$C$11,2,0) -> Deepak Nair | P18: =IF(I18="Denied",G18,0) -> 0
A19: C20018 | B19: P-1104 | C19: City Care Clinic | D19: Medicare | E19: 46049 | F19: 46060 | G19: 5725 | I19: Pending | K19: Vikas R | L19: =MIS_Report!$B$2-F19 -> 250 | M19: {=_xlfn.IFS(L19<=30,"0-30",L19<=60,"31-60",L19<=90,"61-90",TRUE,"90+")} -> 90+ | N19: =IF(I19="Pending",G19-H19,0) -> 5725 | O19: =VLOOKUP(K19,Agents!$A$1:$C$11,2,0) -> Sunita Rao | P19: =IF(I19="Denied",G19,0) -> 0
A20: C20019 | B20: P-1498 | C20: Sunrise Hospital | D20: Medicare | E20: 46241 | F20: 46251 | G20: 1825 | H20: 1439.84 | I20: Paid | K20: Amit V | L20: =MIS_Report!$B$2-F20 -> 59 | M20: {=_xlfn.IFS(L20<=30,"0-30",L20<=60,"31-60",L20<=90,"61-90",TRUE,"90+")} -> 31-60 | N20: =IF(I20="Pending",G20-H20,0) -> 0 | O20: =VLOOKUP(K20,Agents!$A$1:$C$11,2,0) -> Manish Arora | P20: =IF(I20="Denied",G20,0) -> 0
A21: C20020 | B21: P-1071 | C21: City Care Clinic | D21: Humana | E21: 46240 | F21: 46253 | G21: 13650 | I21: Pending | K21: Anjali T | L21: =MIS_Report!$B$2-F21 -> 57 | M21: {=_xlfn.IFS(L21<=30,"0-30",L21<=60,"31-60",L21<=90,"61-90",TRUE,"90+")} -> 31-60 | N21: =IF(I21="Pending",G21-H21,0) -> 13650 | O21: =VLOOKUP(K21,Agents!$A$1:$C$11,2,0) -> Deepak Nair | P21: =IF(I21="Denied",G21,0) -> 0
A22: C20021 | B22: P-1374 | C22: Apex Ortho Center | D22: Medicaid | E22: 46194 | F22: 46206 | G22: 1150 | H22: 882.06 | I22: Paid | K22: Priya K | L22: =MIS_Report!$B$2-F22 -> 104 | M22: {=_xlfn.IFS(L22<=30,"0-30",L22<=60,"31-60",L22<=90,"61-90",TRUE,"90+")} -> 90+ | N22: =IF(I22="Pending",G22-H22,0) -> 0 | O22: =VLOOKUP(K22,Agents!$A$1:$C$11,2,0) -> Manish Arora | P22: =IF(I22="Denied",G22,0) -> 0
A23: C20022 | B23: P-1377 | C23: Sunrise Hospital | D23: Blue Cross | E23: 46044 | F23: 46061 | G23: 14275 | H23: 13865.48 | I23: Paid | K23: Pooja M | L23: =MIS_Report!$B$2-F23 -> 249 | M23: {=_xlfn.IFS(L23<=30,"0-30",L23<=60,"31-60",L23<=90,"61-90",TRUE,"90+")} -> 90+ | N23: =IF(I23="Pending",G23-H23,0) -> 0 | O23: =VLOOKUP(K23,Agents!$A$1:$C$11,2,0) -> Sunita Rao | P23: =IF(I23="Denied",G23,0) -> 0
A24: C20023 | B24: P-1446 | C24: Green Valley Health | D24: Humana | E24: 46198 | F24: 46203 | G24: 12400 | I24: Pending | K24: Rahul S | L24: =MIS_Report!$B$2-F24 -> 107 | M24: {=_xlfn.IFS(L24<=30,"0-30",L24<=60,"31-60",L24<=90,"61-90",TRUE,"90+")} -> 90+ | N24: =IF(I24="Pending",G24-H24,0) -> 12400 | O24: =VLOOKUP(K24,Agents!$A$1:$C$11,2,0) -> Manish Arora | P24: =IF(I24="Denied",G24,0) -> 0
A25: C20024 | B25: P-1006 | C25: City Care Clinic | D25: Medicare | E25: 46275 | F25: 46278 | G25: 10075 | I25: Pending | K25: Priya K | L25: =MIS_Report!$B$2-F25 -> 32 | M25: {=_xlfn.IFS(L25<=30,"0-30",L25<=60,"31-60",L25<=90,"61-90",TRUE,"90+")} -> 31-60 | N25: =IF(I25="Pending",G25-H25,0) -> 10075 | O25: =VLOOKUP(K25,Agents!$A$1:$C$11,2,0) -> Manish Arora | P25: =IF(I25="Denied",G25,0) -> 0
A26: C20025 | B26: P-1225 | C26: Green Valley Health | D26: Blue Cross | E26: 46138 | F26: 46154 | G26: 8750 | H26: 7100 | I26: Paid | K26: Priya K | L26: =MIS_Report!$B$2-F26 -> 156 | M26: {=_xlfn.IFS(L26<=30,"0-30",L26<=60,"31-60",L26<=90,"61-90",TRUE,"90+")} -> 90+ | N26: =IF(I26="Pending",G26-H26,0) -> 0 | O26: =VLOOKUP(K26,Agents!$A$1:$C$11,2,0) -> Manish Arora | P26: =IF(I26="Denied",G26,0) -> 0
A27: C20026 | B27: P-1044 | C27: Green Valley Health | D27: Medicare | E27: 46269 | F27: 46288 | G27: 1050 | I27: Pending | K27: Priya K | L27: =MIS_Report!$B$2-F27 -> 22 | M27: {=_xlfn.IFS(L27<=30,"0-30",L27<=60,"31-60",L27<=90,"61-90",TRUE,"90+")} -> 0-30 | N27: =IF(I27="Pending",G27-H27,0) -> 1050 | O27: =VLOOKUP(K27,Agents!$A$1:$C$11,2,0) -> Manish Arora | P27: =IF(I27="Denied",G27,0) -> 0
A28: C20027 | B28: P-1188 | C28: Apex Ortho Center | D28: Medicare | E28: 46259 | F28: 46277 | G28: 6825 | I28: Pending | K28: Kavita D | L28: =MIS_Report!$B$2-F28 -> 33 | M28: {=_xlfn.IFS(L28<=30,"0-30",L28<=60,"31-60",L28<=90,"61-90",TRUE,"90+")} -> 31-60 | N28: =IF(I28="Pending",G28-H28,0) -> 6825 | O28: =VLOOKUP(K28,Agents!$A$1:$C$11,2,0) -> Deepak Nair | P28: =IF(I28="Denied",G28,0) -> 0
A29: C20028 | B29: P-1255 | C29: Sunrise Hospital | D29: Medicaid | E29: 46107 | F29: 46126 | G29: 4625 | H29: 4479.94 | I29: Paid | K29: Sandeep Y | L29: =MIS_Report!$B$2-F29 -> 184 | M29: {=_xlfn.IFS(L29<=30,"0-30",L29<=60,"31-60",L29<=90,"61-90",TRUE,"90+")} -> 90+ | N29: =IF(I29="Pending",G29-H29,0) -> 0 | O29: =VLOOKUP(K29,Agents!$A$1:$C$11,2,0) -> Sunita Rao | P29: =IF(I29="Denied",G29,0) -> 0
A30: C20029 | B30: P-1196 | C30: Sunrise Hospital | D30: UnitedHealthcare | E30: 46108 | F30: 46124 | G30: 5425 | I30: Pending | K30: Pooja M | L30: =MIS_Report!$B$2-F30 -> 186 | M30: {=_xlfn.IFS(L30<=30,"0-30",L30<=60,"31-60",L30<=90,"61-90",TRUE,"90+")} -> 90+ | N30: =IF(I30="Pending",G30-H30,0) -> 5425 | O30: =VLOOKUP(K30,Agents!$A$1:$C$11,2,0) -> Sunita Rao | P30: =IF(I30="Denied",G30,0) -> 0
A31: C20030 | B31: P-1364 | C31: City Care Clinic | D31: Humana | E31: 46123 | F31: 46130 | G31: 3725 | H31: 0 | I31: Denied | J31: Medical Necessity Not Met | K31: Sandeep Y | L31: =MIS_Report!$B$2-F31 -> 180 | M31: {=_xlfn.IFS(L31<=30,"0-30",L31<=60,"31-60",L31<=90,"61-90",TRUE,"90+")} -> 90+ | N31: =IF(I31="Pending",G31-H31,0) -> 0 | O31: =VLOOKUP(K31,Agents!$A$1:$C$11,2,0) -> Sunita Rao | P31: =IF(I31="Denied",G31,0) -> 3725
A32: C20031 | B32: P-1195 | C32: Green Valley Health | D32: Cigna | E32: 46103 | F32: 46109 | G32: 11825 | H32: 0 | I32: Denied | J32: Medical Necessity Not Met | K32: Kavita D | L32: =MIS_Report!$B$2-F32 -> 201 | M32: {=_xlfn.IFS(L32<=30,"0-30",L32<=60,"31-60",L32<=90,"61-90",TRUE,"90+")} -> 90+ | N32: =IF(I32="Pending",G32-H32,0) -> 0 | O32: =VLOOKUP(K32,Agents!$A$1:$C$11,2,0) -> Deepak Nair | P32: =IF(I32="Denied",G32,0) -> 11825
A33: C20032 | B33: P-1142 | C33: City Care Clinic | D33: Cigna | E33: 46241 | F33: 46254 | G33: 2200 | I33: Pending | K33: Sandeep Y | L33: =MIS_Report!$B$2-F33 -> 56 | M33: {=_xlfn.IFS(L33<=30,"0-30",L33<=60,"31-60",L33<=90,"61-90",TRUE,"90+")} -> 31-60 | N33: =IF(I33="Pending",G33-H33,0) -> 2200 | O33: =VLOOKUP(K33,Agents!$A$1:$C$11,2,0) -> Sunita Rao | P33: =IF(I33="Denied",G33,0) -> 0
A34: C20033 | B34: P-1012 | C34: Apex Ortho Center | D34: Medicaid | E34: 46192 | F34: 46204 | G34: 14725 | H34: 11112.58 | I34: Paid | K34: Amit V | L34: =MIS_Report!$B$2-F34 -> 106 | M34: {=_xlfn.IFS(L34<=30,"0-30",L34<=60,"31-60",L34<=90,"61-90",TRUE,"90+")} -> 90+ | N34: =IF(I34="Pending",G34-H34,0) -> 0 | O34: =VLOOKUP(K34,Agents!$A$1:$C$11,2,0) -> Manish Arora | P34: =IF(I34="Denied",G34,0) -> 0
A35: C20034 | B35: P-1188 | C35: City Care Clinic | D35: Cigna | E35: 46041 | F35: 46047 | G35: 11725 | H35: 9825.11 | I35: Paid | K35: Neha G | L35: =MIS_Report!$B$2-F35 -> 263 | M35: {=_xlfn.IFS(L35<=30,"0-30",L35<=60,"31-60",L35<=90,"61-90",TRUE,"90+")} -> 90+ | N35: =IF(I35="Pending",G35-H35,0) -> 0 | O35: =VLOOKUP(K35,Agents!$A$1:$C$11,2,0) -> Manish Arora | P35: =IF(I35="Denied",G35,0) -> 0
A36: C20035 | B36: P-1386 | C36: Green Valley Health | D36: UnitedHealthcare | E36: 46255 | F36: 46266 | G36: 4850 | I36: Pending | K36: Rahul S | L36: =MIS_Report!$B$2-F36 -> 44 | M36: {=_xlfn.IFS(L36<=30,"0-30",L36<=60,"31-60",L36<=90,"61-90",TRUE,"90+")} -> 31-60 | N36: =IF(I36="Pending",G36-H36,0) -> 4850 | O36: =VLOOKUP(K36,Agents!$A$1:$C$11,2,0) -> Manish Arora | P36: =IF(I36="Denied",G36,0) -> 0
A37: C20036 | B37: P-1256 | C37: Sunrise Hospital | D37: Aetna | E37: 46104 | F37: 46114 | G37: 7250 | H37: 7076.5 | I37: Paid | K37: Neha G | L37: =MIS_Report!$B$2-F37 -> 196 | M37: {=_xlfn.IFS(L37<=30,"0-30",L37<=60,"31-60",L37<=90,"61-90",TRUE,"90+")} -> 90+ | N37: =IF(I37="Pending",G37-H37,0) -> 0 | O37: =VLOOKUP(K37,Agents!$A$1:$C$11,2,0) -> Manish Arora | P37: =IF(I37="Denied",G37,0) -> 0
A38: C20037 | B38: P-1465 | C38: City Care Clinic | D38: Aetna | E38: 46051 | F38: 46067 | G38: 10225 | H38: 8502.05 | I38: Paid | K38: Kavita D | L38: =MIS_Report!$B$2-F38 -> 243 | M38: {=_xlfn.IFS(L38<=30,"0-30",L38<=60,"31-60",L38<=90,"61-90",TRUE,"90+")} -> 90+ | N38: =IF(I38="Pending",G38-H38,0) -> 0 | O38: =VLOOKUP(K38,Agents!$A$1:$C$11,2,0) -> Deepak Nair | P38: =IF(I38="Denied",G38,0) -> 0
A39: C20038 | B39: P-1104 | C39: City Care Clinic | D39: Cigna | E39: 46267 | F39: 46280 | G39: 12150 | I39: Pending | K39: Priya K | L39: =MIS_Report!$B$2-F39 -> 30 | M39: {=_xlfn.IFS(L39<=30,"0-30",L39<=60,"31-60",L39<=90,"61-90",TRUE,"90+")} -> 0-30 | N39: =IF(I39="Pending",G39-H39,0) -> 12150 | O39: =VLOOKUP(K39,Agents!$A$1:$C$11,2,0) -> Manish Arora | P39: =IF(I39="Denied",G39,0) -> 0
A40: C20039 | B40: P-1500 | C40: Apex Ortho Center | D40: UnitedHealthcare | E40: 46122 | F40: 46132 | G40: 10275 | I40: Pending | K40: Pooja M | L40: =MIS_Report!$B$2-F40 -> 178 | M40: {=_xlfn.IFS(L40<=30,"0-30",L40<=60,"31-60",L40<=90,"61-90",TRUE,"90+")} -> 90+ | N40: =IF(I40="Pending",G40-H40,0) -> 10275 | O40: =VLOOKUP(K40,Agents!$A$1:$C$11,2,0) -> Sunita Rao | P40: =IF(I40="Denied",G40,0) -> 0
...

Sheet Claims_Raw
A1: Claim ID | B1: Patient ID | C1: Facility | D1: Payer | E1: DOS | F1: Submission Date | G1: Billed Amount | H1: Paid Amount | I1: Status | J1: Denial Reason | K1: Assigned Agent
A2: C20001 | B2: P-1411 | C2: Green Valley Health | D2: UnitedHealthcare | E2: 46234 | F2: 46254 | G2: 12200 | H2: 0 | I2: Denied | J2: Duplicate Claim | K2: Amit V
A3: C20002 | B3: P-1324 | C3: City Care Clinic | D3: UnitedHealthcare | E3: 46054 | F3: 46071 | G3: 8050 | H3: 7652.9 | I3: Paid | K3: Vikas R
A4: C20003 | B4: P-1032 | C4: City Care Clinic | D4: Medicare | E4: 46246 | F4: 46254 | G4: 675 | I4: Pending | K4: Neha G
A5: C20004 | B5: P-1327 | C5: Apex Ortho Center | D5: UnitedHealthcare | E5: 46021 | F5: 46038 | G5: 8650 | H5: 0 | I5: Denied | J5: Coding Error | K5: Priya K
A6: C20005 | B6: P-1477 | C6: City Care Clinic | D6: Cigna | E6: 46246 | F6: 46257 | G6: 10700 | I6: Pending | K6: Pooja M
A7: C20006 | B7: P-1055 | C7: Apex Ortho Center | D7: Aetna | E7: 46121 | F7: 46140 | G7: 7675 | H7: 4594 | I7: Paid | K7: Rahul S
A8: C20007 | B8: P-1026 | C8: Green Valley Health | D8: Aetna | E8: 46014 | F8: 46023 | G8: 5650 | I8: Pending | K8: Vikas R
A9: C20008 | B9: P-1398 | C9: Apex Ortho Center | D9: Medicaid | E9: 46232 | F9: 46237 | G9: 14775 | I9: Pending | K9: Sandeep Y
A10: C20009 | B10: P-1051 | C10: City Care Clinic | D10: Medicare | E10: 46190 | F10: 46193 | G10: 10775 | H10: 7120.92 | I10: Paid | K10: Anjali T
A11: C20010 | B11: P-1067 | C11: Green Valley Health | D11: Cigna | E11: 46093 | F11: 46113 | G11: 5100 | H11: 4484.7 | I11: Paid | K11: Priya K
A12: C20011 | B12: P-1303 | C12: Apex Ortho Center | D12: Self Pay | E12: 46209 | F12: 46225 | G12: 5725 | H12: 0 | I12: Denied | J12: Incorrect Patient Info | K12: Rahul S
A13: C20012 | B13: P-1308 | C13: City Care Clinic | D13: Medicare | E13: 46122 | F13: 46130 | G13: 10375 | I13: Pending | K13: Amit V
A14: C20013 | B14: P-1197 | C14: City Care Clinic | D14: Medicare | E14: 46115 | F14: 46132 | G14: 6900 | H14: 6373.05 | I14: Paid | K14: Neha G
A15: C20014 | B15: P-1247 | C15: Sunrise Hospital | D15: Blue Cross | E15: 46144 | F15: 46147 | G15: 9725 | H15: 9546.16 | I15: Paid | K15: Amit V
A16: C20015 | B16: P-1127 | C16: Sunrise Hospital | D16: Medicare | E16: 46089 | F16: 46101 | G16: 6125 | I16: Pending | K16: Rohit B
A17: C20016 | B17: P-1019 | C17: Apex Ortho Center | D17: Medicaid | E17: 46108 | F17: 46123 | G17: 12650 | H17: 7548.61 | I17: Paid | K17: Vikas R
A18: C20017 | B18: P-1035 | C18: Sunrise Hospital | D18: Medicaid | E18: 46138 | F18: 46154 | G18: 12850 | H18: 11232.94 | I18: Paid | K18: Rohit B
A19: C20018 | B19: P-1104 | C19: City Care Clinic | D19: Medicare | E19: 46049 | F19: 46060 | G19: 5725 | I19: Pending | K19: Vikas R
A20: C20019 | B20: P-1498 | C20: Sunrise Hospital | D20: Medicare | E20: 46241 | F20: 46251 | G20: 1825 | H20: 1439.84 | I20: Paid | K20: Amit V
A21: C20020 | B21: P-1071 | C21: City Care Clinic | D21: Humana | E21: 46240 | F21: 46253 | G21: 13650 | I21: Pending | K21: Anjali T
A22: C20021 | B22: P-1374 | C22: Apex Ortho Center | D22: Medicaid | E22: 46194 | F22: 46206 | G22: 1150 | H22: 882.06 | I22: Paid | K22: Priya K
A23: C20022 | B23: P-1377 | C23: Sunrise Hospital | D23: Blue Cross | E23: 46044 | F23: 46061 | G23: 14275 | H23: 13865.48 | I23: Paid | K23: Pooja M
A24: C20023 | B24: P-1446 | C24: Green Valley Health | D24: Humana | E24: 46198 | F24: 46203 | G24: 12400 | I24: Pending | K24: Rahul S
A25: C20024 | B25: P-1006 | C25: City Care Clinic | D25: Medicare | E25: 46275 | F25: 46278 | G25: 10075 | I25: Pending | K25: Priya K
A26: C20025 | B26: P-1225 | C26: Green Valley Health | D26: Blue Cross | E26: 46138 | F26: 46154 | G26: 8750 | H26: 7100 | I26: Paid | K26: Priya K
A27: C20026 | B27: P-1044 | C27: Green Valley Health | D27: Medicare | E27: 46269 | F27: 46288 | G27: 1050 | I27: Pending | K27: Priya K
A28: C20027 | B28: P-1188 | C28: Apex Ortho Center | D28: Medicare | E28: 46259 | F28: 46277 | G28: 6825 | I28: Pending | K28: Kavita D
A29: C20028 | B29: P-1255 | C29: Sunrise Hospital | D29: Medicaid | E29: 46107 | F29: 46126 | G29: 4625 | H29: 4479.94 | I29: Paid | K29: Sandeep Y
A30: C20029 | B30: P-1196 | C30: Sunrise Hospital | D30: UnitedHealthcare | E30: 46108 | F30: 46124 | G30: 5425 | I30: Pending | K30: Pooja M
A31: C20030 | B31: P-1364 | C31: City Care Clinic | D31: Humana | E31: 46123 | F31: 46130 | G31: 3725 | H31: 0 | I31: Denied | J31: Medical Necessity Not Met | K31: Sandeep Y
A32: C20031 | B32: P-1195 | C32: Green Valley Health | D32: Cigna | E32: 46103 | F32: 46109 | G32: 11825 | H32: 0 | I32: Denied | J32: Medical Necessity Not Met | K32: Kavita D
A33: C20032 | B33: P-1142 | C33: City Care Clinic | D33: Cigna | E33: 46241 | F33: 46254 | G33: 2200 | I33: Pending | K33: Sandeep Y
A34: C20033 | B34: P-1012 | C34: Apex Ortho Center | D34: Medicaid | E34: 46192 | F34: 46204 | G34: 14725 | H34: 11112.58 | I34: Paid | K34: Amit V
A35: C20034 | B35: P-1188 | C35: City Care Clinic | D35: Cigna | E35: 46041 | F35: 46047 | G35: 11725 | H35: 9825.11 | I35: Paid | K35: Neha G
A36: C20035 | B36: P-1386 | C36: Green Valley Health | D36: UnitedHealthcare | E36: 46255 | F36: 46266 | G36: 4850 | I36: Pending | K36: Rahul S
A37: C20036 | B37: P-1256 | C37: Sunrise Hospital | D37: Aetna | E37: 46104 | F37: 46114 | G37: 7250 | H37: 7076.5 | I37: Paid | K37: Neha G
A38: C20037 | B38: P-1465 | C38: City Care Clinic | D38: Aetna | E38: 46051 | F38: 46067 | G38: 10225 | H38: 8502.05 | I38: paid | K38: Kavita D
A39: C20038 | B39: P-1104 | C39: City Care Clinic | D39: Cigna | E39: 46267 | F39: 46280 | G39: 12150 | I39: Pending | K39: Priya K
A40: C20039 | B40: P-1500 | C40: Apex Ortho Center | D40: UnitedHealthcare | E40: 46122 | F40: 46132 | G40: 10275 | I40: PENDING | K40: Pooja M
...

Sheet MIS_Report
A1: Report_Date | B1: Date_Type
B2: 46310
A3: KPI | B3: Value
A4: Total Claims | B4: =COUNTA(Claims_Clean!A:A)-1 -> 1000
A5: Total Billed | B5: =SUM(Claims_Clean!G2:G1001) -> 7777300
A6: Total Collected | B6: =SUM(Claims_Clean!H:H) -> 3373662
A7: Total Outstanding | B7: =SUM(Claims_Clean!N2:N1001) -> 2534725
A8: Denied Claims | B8: =COUNTIF(Claims_Clean!I2:I1001,"Denied") -> 114
A9: Denial Rate | B9: =B8/B4 -> 0.114
A10: Collected Rate | B10: =B6/B5 -> 0.43378319
A11: Outstanding 90+ | B11: =SUMIF(Claims_Clean!M2:M1001,"90+",Claims_Clean!N2:N1001) -> 1287000
A12: 90+ % of Outstanding | B12: =B11/B7 -> 0.50774739

Sheet Agents
A1: Agent | B1: Team Lead | C1: Daily Target (Accounts)
A2: Rahul S | B2: Manish Arora | C2: 45
A3: Priya K | B3: Manish Arora | C3: 50
A4: Amit V | B4: Manish Arora | C4: 40
A5: Neha G | B5: Manish Arora | C5: 45
A6: Sandeep Y | B6: Sunita Rao | C6: 50
A7: Pooja M | B7: Sunita Rao | C7: 45
A8: Vikas R | B8: Sunita Rao | C8: 40
A9: Anjali T | B9: Deepak Nair | C9: 50
A10: Rohit B | B10: Deepak Nair | C10: 45
A11: Kavita D | B11: Deepak Nair | C11: 40

Sheet Daily_Productivity
A1: Work Date | B1: Agent | C1: Accounts Worked | D1: Hours Logged | E1: Quality %
A2: 46266 | B2: Rahul S | C2: 37 | D2: 7.8 | E2: 91
A3: 46266 | B3: Priya K | C3: 46 | D3: 8.1 | E3: 90.2
A4: 46266 | B4: Amit V | C4: 34 | D4: 8.2 | E4: 98.5
A5: 46266 | B5: Neha G | C5: 47 | D5: 7.3 | E5: 90.4
A6: 46266 | B6: Sandeep Y | C6: 49 | D6: 7.9 | E6: 94.9
A7: 46266 | B7: Pooja M | C7: 47 | D7: 8.1 | E7: 95.9
A8: 46266 | B8: Vikas R | C8: 33 | D8: 8.9 | E8: 92.1
A9: 46266 | B9: Anjali T | C9: 49 | D9: 7.7 | E9: 98
A10: 46266 | B10: Rohit B | C10: 48 | D10: 8.8 | E10: 95.4
A11: 46266 | B11: Kavita D | C11: 48 | D11: 8.1 | E11: 91.7
A12: 46267 | B12: Rahul S | C12: 34 | D12: 7.5 | E12: 91.1
A13: 46267 | B13: Priya K | C13: 40 | D13: 8.1 | E13: 94.5
... A315: 46310 | B315: Kavita D | C315: 28 | D315: 8.8 | E315: 90.8

Sheet Productivity_Report
A1: Agent | B1: Days worked | C1: Total Accounts | D1: Daily Target | E1: Target Total | F1: Productivity % | G1: Avg Quality %
A2: {=Agents!A2:A11} -> Rahul S | B2: {=COUNTIF(Daily_Productivity!B2:B315,_xlfn.ANCHORARRAY(Productivity_Report!A2))} -> 31 | C2: {=SUMIF(Daily_Productivity!B2:B315,_xlfn.ANCHORARRAY(Productivity_Report!A2),Daily_Productivity!C2:C315)} -> 1331 | D2: =VLOOKUP(A2,Agents!$A$2:$C$11,3,0) -> 45 | E2: =B2*D2 -> 1395 | F2: =C2/E2 -> 0.95412186 | G2: {=AVERAGEIF(Daily_Productivity!B2:B315,_xlfn.ANCHORARRAY(Productivity_Report!A2),Daily_Productivity!E2:E315)} -> 93.577419
A3: Priya K | B3: 31 | C3: 1436 | D3: =VLOOKUP(A3,Agents!$A$2:$C$11,3,0) -> 50 | E3: =B3*D3 -> 1550 | F3: =C3/E3 -> 0.92645161 | G3: 92.958065
A4: Amit V | B4: 32 | C4: 1168 | D4: =VLOOKUP(A4,Agents!$A$2:$C$11,3,0) -> 40 | E4: =B4*D4 -> 1280 | F4: =C4/E4 -> 0.9125 | G4: 94.2
A5: Neha G | B5: 31 | C5: 1393 | D5: =VLOOKUP(A5,Agents!$A$2:$C$11,3,0) -> 45 | E5: =B5*D5 -> 1395 | F5: =C5/E5 -> 0.99856631 | G5: 94.551613
A6: Sandeep Y | B6: 33 | C6: 1636 | D6: =VLOOKUP(A6,Agents!$A$2:$C$11,3,0) -> 50 | E6: =B6*D6 -> 1650 | F6: =C6/E6 -> 0.99151515 | G6: 92.790909
A7: Pooja M | B7: 31 | C7: 1346 | D7: =VLOOKUP(A7,Agents!$A$2:$C$11,3,0) -> 45 | E7: =B7*D7 -> 1395 | F7: =C7/E7 -> 0.96487455 | G7: 93.445161
A8: Vikas R | B8: 32 | C8: 1211 | D8: =VLOOKUP(A8,Agents!$A$2:$C$11,3,0) -> 40 | E8: =B8*D8 -> 1280 | F8: =C8/E8 -> 0.94609375 | G8: 94.05
A9: Anjali T | B9: 32 | C9: 1580 | D9: =VLOOKUP(A9,Agents!$A$2:$C$11,3,0) -> 50 | E9: =B9*D9 -> 1600 | F9: =C9/E9 -> 0.9875 | G9: 93.7
A10: Rohit B | B10: 31 | C10: 1310 | D10: =VLOOKUP(A10,Agents!$A$2:$C$11,3,0) -> 45 | E10: =B10*D10 -> 1395 | F10: =C10/E10 -> 0.9390681 | G10: 93.909677
A11: Kavita D | B11: 30 | C11: 1135 | D11: =VLOOKUP(A11,Agents!$A$2:$C$11,3,0) -> 40 | E11: =B11*D11 -> 1200 | F11: =C11/E11 -> 0.94583333 | G11: 93.446667
A13: Key Insights
A14: Team productivity | B14: =SUM(_xlfn.ANCHORARRAY(C2))/SUM(E2:E11) -> 0.95799151
A15: Team productivity is 95.8% against target; no agent has reached 100%.
A16: Top performers: Neha G (99.9%), Sandeep Y (99.2%), Anjali T (98.8%).
A17: Amit V is the lowest at 91.3%, while quality is similar across the team (92.8 to 94.6), so the gap is in speed, not accuracy.
A18: Recommendation: review Amit V’s workload and process with the team lead.

Sheet Pivots
A1: Healthcare MIS
A2: KPI cards
A3: Total Outstanding | B3: =MIS_Report!B7 -> 2534725
A4: Denial Rate | B4: =MIS_Report!B9 -> 0.114
A5: Collected Rate | B5: =MIS_Report!B10 -> 0.43378319
A6: 90+ % of Outstanding | B6: =MIS_Report!B12 -> 0.50774739
A9: Row Labels | B9: Sum of Outstanding_Amount
A10: 0-30 | B10: 510950
A11: 31-60 | B11: 412150
A12: 61-90 | B12: 324625
A13: 90+ | B13: 1287000
A14: Grand Total | B14: 2534725
A17: Row Labels | B17: Sum of Outstanding_Amount
A18: Unknown | B18: 54350
A19: Self Pay | B19: 76700
A20: Humana | B20: 216125
A21: Cigna | B21: 239275
A22: Medicaid | B22: 295275
A23: Aetna | B23: 331875
A24: UnitedHealthcare | B24: 342100
A25: Blue Cross | B25: 389050
A26: Medicare | B26: 589975
A27: Grand Total | B27: 2534725
A31: Row Labels | B31: Sum of Denied_Amount
A32: Duplicate Claim | B32: 68525
A33: Timely Filing Exceeded | B33: 90175
A34: Incorrect Patient Info | B34: 97250
A35: Missing Prior Authorization | B35: 105600
A36: Medical Necessity Not Met | B36: 133525
A37: Patient Not Eligible | B37: 188775
A38: Coding Error | B38: 216000
A39: Grand Total | B39: 899850
A43: Row Labels | B43: Sum of Productivity %
A44: Amit V | B44: 0.9125
A45: Priya K | B45: 0.92645161
A46: Rohit B | B46: 0.9390681
A47: Kavita D | B47: 0.94583333
A48: Vikas R | B48: 0.94609375
A49: Rahul S | B49: 0.95412186
A50: Pooja M | B50: 0.96487455
...

Sheet MIS_Dashboard
A1: Healthcare MIS Dashboard
A4: Total Claims | C4: Total Billed (Lakh) | E4: Collected (Lakh) | G4: Outstanding (Lakh) | I4: Denial Rate | K4: 90+ % of Outstanding
A5: =MIS_Report!B4 -> 1000 | C5: =MIS_Report!B5/100000 -> 77.773 | E5: =MIS_Report!B6/100000 -> 33.73662 | G5: =MIS_Report!B7/100000 -> 25.34725 | I5: =MIS_Report!B9 -> 0.114 | K5: =MIS_Report!B12 -> 0.50774739
A35: Key Insights
A36: 90+ day claims hold 50.8% of outstanding (12.87 lakh of 25.35 lakh).
A37: Medicare holds the largest share of outstanding (5.90 lakh, about 23%).
A38: Coding Error and Patient Not Eligible make up 45% of denied amount, and both are preventable before submission.
A39: Team productivity is 95.8% of target; Amit V is lowest at 91.3% while quality is similar across agents.
A40: Recommendation: work the 90+ bucket first, add pre-submission coding checks, and review Amit V's workload.
A41: Dummy data for practice. Report date: 15-Oct-2026.
